Workbook

Sheet Overzicht
A1: Belgische bedrijven – kandidaten voor gratis test (onderzoek tijdsbesparing door AI)
A3: Verzameld op 27-28 september 2026 via webzoekresultaten (fragmenten van bedrijfswebsites en openbare bedrijvengidsen).
A4: Bedrijfswebsites, Voka/Unizo-ledenlijsten en Trends Top konden niet rechtstreeks geopend worden (netwerkbeleid van de omgeving). Alle gegevens zijn dus niet op de website zelf nagekeken — controleer vóór contact.
A5: Groottecriteria (medewerkers, aantal panden) staan zelden publiek: de kolom 'Opmerking' zegt wat bekend is; 'omvang niet geverifieerd' betekent dat het criterium niet bevestigd is.
A6: Lege cel bij e-mail/telefoon = niet gevonden in de zoekresultaten. Persoonlijke adressen zijn gemarkeerd in de opmerking.
A7: Doel was 100 per sector; de zoeklimiet van de sessie (200 zoekopdrachten) liet dit aantal niet toe.
A9: Sector | B9: Subcategorie | C9: Aantal | D9: Met e-mail
A10: Boekhouding | B10: Zelfstandige boekhouder | C10: =COUNTIF('Boekhouding'!$C:$C,B10) | D10: =COUNTIFS('Boekhouding'!$C:$C,B10,'Boekhouding'!$F:$F,"?*")
A11: Boekhouding | B11: Klein kantoor (2-10 medewerkers) | C11: =COUNTIF('Boekhouding'!$C:$C,B11) | D11: =COUNTIFS('Boekhouding'!$C:$C,B11,'Boekhouding'!$F:$F,"?*")
A12: Boekhouding | B12: Groter accountantskantoor (meerdere vestigingen) | C12: =COUNTIF('Boekhouding'!$C:$C,B12) | D12: =COUNTIFS('Boekhouding'!$C:$C,B12,'Boekhouding'!$F:$F,"?*")
A13: Boekhouding | B13: Sociaal secretariaat | C13: =COUNTIF('Boekhouding'!$C:$C,B13) | D13: =COUNTIFS('Boekhouding'!$C:$C,B13,'Boekhouding'!$F:$F,"?*")
A14: Boekhouding | B14: Totaal sector (doel: 100) | C14: =SUM(C10:C13) | D14: =SUM(D10:D13)
A15: Advocaten & consultancy | B15: Klein advocatenkantoor (≤5) | C15: =COUNTIF('Advocaten & consultancy'!$C:$C,B15) | D15: =COUNTIFS('Advocaten & consultancy'!$C:$C,B15,'Advocaten & consultancy'!$F:$F,"?*")
A16: Advocaten & consultancy | B16: Notariskantoor | C16: =COUNTIF('Advocaten & consultancy'!$C:$C,B16) | D16: =COUNTIFS('Advocaten & consultancy'!$C:$C,B16,'Advocaten & consultancy'!$F:$F,"?*")
A17: Advocaten & consultancy | B17: Bedrijfsadvies / HR-consultancy | C17: =COUNTIF('Advocaten & consultancy'!$C:$C,B17) | D17: =COUNTIFS('Advocaten & consultancy'!$C:$C,B17,'Advocaten & consultancy'!$F:$F,"?*")
A18: Advocaten & consultancy | B18: Totaal sector (doel: 100) | C18: =SUM(C15:C17) | D18: =SUM(D15:D17)
A19: Transport & logistiek | B19: Transportbedrijf (eigen wagenpark) | C19: =COUNTIF('Transport & logistiek'!$C:$C,B19) | D19: =COUNTIFS('Transport & logistiek'!$C:$C,B19,'Transport & logistiek'!$F:$F,"?*")
A20: Transport & logistiek | B20: Koeriersbedrijf | C20: =COUNTIF('Transport & logistiek'!$C:$C,B20) | D20: =COUNTIFS('Transport & logistiek'!$C:$C,B20,'Transport & logistiek'!$F:$F,"?*")
A21: Transport & logistiek | B21: Verhuisfirma | C21: =COUNTIF('Transport & logistiek'!$C:$C,B21) | D21: =COUNTIFS('Transport & logistiek'!$C:$C,B21,'Transport & logistiek'!$F:$F,"?*")
A22: Transport & logistiek | B22: Totaal sector (doel: 100) | C22: =SUM(C19:C21) | D22: =SUM(D19:D21)
A23: Bouw | B23: Algemene aannemer | C23: =COUNTIF('Bouw'!$C:$C,B23) | D23: =COUNTIFS('Bouw'!$C:$C,B23,'Bouw'!$F:$F,"?*")
A24: Bouw | B24: Installatiebedrijf (elektriciteit) | C24: =COUNTIF('Bouw'!$C:$C,B24) | D24: =COUNTIFS('Bouw'!$C:$C,B24,'Bouw'!$F:$F,"?*")
A25: Bouw | B25: Installatiebedrijf (sanitair/verwarming) | C25: =COUNTIF('Bouw'!$C:$C,B25) | D25: =COUNTIFS('Bouw'!$C:$C,B25,'Bouw'!$F:$F,"?*")
A26: Bouw | B26: Renovatiebedrijf | C26: =COUNTIF('Bouw'!$C:$C,B26) | D26: =COUNTIFS('Bouw'!$C:$C,B26,'Bouw'!$F:$F,"?*")
A27: Bouw | B27: Totaal sector (doel: 100) | C27: =SUM(C23:C26) | D27: =SUM(D23:D26)
A28: Vastgoed | B28: Makelaarskantoor | C28: =COUNTIF('Vastgoed'!$C:$C,B28) | D28: =COUNTIFS('Vastgoed'!$C:$C,B28,'Vastgoed'!$F:$F,"?*")
A29: Vastgoed | B29: Verhuur- & beheerkantoor | C29: =COUNTIF('Vastgoed'!$C:$C,B29) | D29: =COUNTIFS('Vastgoed'!$C:$C,B29,'Vastgoed'!$F:$F,"?*")
A30: Vastgoed | B30: Syndicus / beheerkantoor | C30: =COUNTIF('Vastgoed'!$C:$C,B30) | D30: =COUNTIFS('Vastgoed'!$C:$C,B30,'Vastgoed'!$F:$F,"?*")
A31: Vastgoed | B31: Kleinere vastgoedontwikkelaar | C31: =COUNTIF('Vastgoed'!$C:$C,B31) | D31: =COUNTIFS('Vastgoed'!$C:$C,B31,'Vastgoed'!$F:$F,"?*")
A32: Vastgoed | B32: Totaal sector (doel: 100) | C32: =SUM(C28:C31) | D32: =SUM(D28:D31)

Sheet Boekhouding
A1: Bedrijfsnaam | B1: Sector | C1: Subcategorie | D1: Website | E1: Plaats | F1: E-mailadres | G1: Telefoon | H1: Opmerking (omvang / verificatie)
A2: Castagna Accountancy | B2: Boekhouding | C2: Zelfstandige boekhouder | D2: castagna.be | E2: Maasmechelen | F2: hello@castagna.be | G2: 0487 95 86 99 | H2: gsm-nummer; waarschijnlijk eenmanszaak
A3: Fidius (Van Bouwel Severinus) | B3: Boekhouding | C3: Zelfstandige boekhouder | D3: fidius.be | E3: Essen | F3: info@fidius.be | H3: fiscalist; geen telefoon in zoekresultaat
A4: GVP Consult | B4: Boekhouding | C4: Zelfstandige boekhouder | E4: Hasselt | G4: 0491 86 96 28 | H4: CommV, kleinschalig; geen publiek e-mailadres gevonden
A5: ND-Consult | B5: Boekhouding | C5: Zelfstandige boekhouder | D5: nd-consult.be | E5: Oostende | H5: fiscaal accountant; contact via formulier op website
A6: Sandra Vandebosch | B6: Boekhouding | C6: Zelfstandige boekhouder | D6: svandebosch.be | E6: Tongeren | G6: 0486 11 52 07 | H6: zelfstandig boekhouder-fiscalist; op afspraak; geen publiek e-mailadres gevonden
A7: A & I Accountants | B7: Boekhouding | C7: Klein kantoor (2-10 medewerkers) | D7: edcweb.be | E7: Aalst | F7: info@edcweb.be | G7: 053 68 43 80 | H7: omvang niet geverifieerd
A8: Academ Accountants | B8: Boekhouding | C8: Klein kantoor (2-10 medewerkers) | D8: academ.be | E8: Izegem | F8: info@academ.be | G8: +32 51 31 70 27 | H8: omvang niet geverifieerd
A9: Accountancy Van Poucke | B9: Boekhouding | C9: Klein kantoor (2-10 medewerkers) | D9: pia.be | E9: Sint-Niklaas | F9: info@accountancyvanpoucke.be | G9: 03 722 91 00 | H9: omvang niet geverifieerd
A10: Accountantskantoor Reynders & Co | B10: Boekhouding | C10: Klein kantoor (2-10 medewerkers) | E10: Sint-Truiden | G10: +32 11 70 20 70 | H10: geen e-mail gevonden
A11: Actabo | B11: Boekhouding | C11: Klein kantoor (2-10 medewerkers) | D11: actabo.be | E11: Sint-Truiden | F11: info@actabo.be | G11: 011 76 33 01 | H11: omvang niet geverifieerd
A12: Adfibo Accountants | B12: Boekhouding | C12: Klein kantoor (2-10 medewerkers) | D12: adfibo.be | E12: Antwerpen | F12: info@adfibo.be | G12: +32 3 644 68 40 | H12: ±7 medewerkers
A13: Adfisc Accountancy | B13: Boekhouding | C13: Klein kantoor (2-10 medewerkers) | D13: adfisc.be | E13: Roeselare | F13: info@adfisc.be | G13: 051 31 77 22 | H13: omvang niet geverifieerd
A14: ATACS | B14: Boekhouding | C14: Klein kantoor (2-10 medewerkers) | D14: atacs.be | E14: Oostende | F14: info@atacs.be | G14: 059 50 94 73 | H14: klein kantoor volgens website
A15: AZ Accounting | B15: Boekhouding | C15: Klein kantoor (2-10 medewerkers) | D15: azaccounting.be | E15: Antwerpen | F15: info@azaccounting.be | G15: +32 3 271 07 77 | H15: omvang niet geverifieerd
A16: B&R Accountants | B16: Boekhouding | C16: Klein kantoor (2-10 medewerkers) | D16: bnr.be | E16: Brasschaat | F16: mail@bnr.be | H16: omvang niet geverifieerd
A17: Birver Accountants | B17: Boekhouding | C17: Klein kantoor (2-10 medewerkers) | D17: birver.be | E17: Brasschaat | F17: info@birver.be | G17: 03 295 87 74 | H17: omvang niet geverifieerd
A18: Bocon | B18: Boekhouding | C18: Klein kantoor (2-10 medewerkers) | D18: bocon.be | E18: Antwerpen | G18: 03 227 55 22 | H18: klein kantoor; geen e-mail gevonden
A19: Boekhoudkantoor Bart Van Nooten | B19: Boekhouding | C19: Klein kantoor (2-10 medewerkers) | D19: boekhoudkantoorvannooten.be | E19: Mol / Turnhout | G19: 014 55 85 99 | H19: 2 kantoren; geen e-mail gevonden
A20: Brasschaats Boekhoudkantoor (BRBO) | B20: Boekhouding | C20: Klein kantoor (2-10 medewerkers) | D20: brasschaatsboekhoudkantoor.be | E20: Brasschaat | F20: info@brbo.be | H20: omvang niet geverifieerd
A21: Comptamatique | B21: Boekhouding | C21: Klein kantoor (2-10 medewerkers) | D21: comptamatique.be | E21: Brussel | G21: 02 511 12 50 | H21: >100 actieve klanten; geen e-mail gevonden
A22: ComptaTeam | B22: Boekhouding | C22: Klein kantoor (2-10 medewerkers) | D22: comptateam.be | E22: Namur | F22: info@comptateam.be | G22: +32 81 72 18 99 | H22: omvang niet geverifieerd
A23: De Neef & Partners (PIA) | B23: Boekhouding | C23: Klein kantoor (2-10 medewerkers) | D23: deneef.be | E23: Sint-Niklaas | F23: info@deneef.be | G23: +32 3 780 98 80 | H23: omvang niet geverifieerd
A24: Dedhac | B24: Boekhouding | C24: Klein kantoor (2-10 medewerkers) | D24: dedhac.be | E24: Heule (Kortrijk) | F24: info@dedhac.be | G24: 056 36 08 33 | H24: vennootschappen en eenmanszaken; omvang niet geverifieerd
A25: Dfisc | B25: Boekhouding | C25: Klein kantoor (2-10 medewerkers) | D25: dfisc.be | E25: Brugge | F25: office@dfisc.be | G25: 050 39 25 23 | H25: omvang niet geverifieerd
A26: Divo | B26: Boekhouding | C26: Klein kantoor (2-10 medewerkers) | D26: accountantdivo.be | E26: Aalter | G26: +32 9 336 82 28 | H26: 2 partners + 2 zelfstandige medewerkers; geen publiek e-mailadres gevonden
A27: EBS Finance West | B27: Boekhouding | C27: Klein kantoor (2-10 medewerkers) | D27: ebsfinancewest.be | E27: Kortrijk | F27: administratie@ebsfinancewest.be | G27: 056 35 45 56 | H27: omvang niet geverifieerd
A28: Eyckmans & Co Accountantskantoor | B28: Boekhouding | C28: Klein kantoor (2-10 medewerkers) | E28: Brugge | G28: 050 32 03 49 | H28: geen e-mail gevonden
A29: FGDS – Fiduciaire Générale de Services | B29: Boekhouding | C29: Klein kantoor (2-10 medewerkers) | D29: fgds.be | E29: Liège | F29: fgds@skynet.be | H29: omvang niet geverifieerd
A30: Fiduciaire Associés | B30: Boekhouding | C30: Klein kantoor (2-10 medewerkers) | D30: fiduciaireassocies.be | E30: Erpent (Namur) | F30: info@fiduciaireassocies.be | G30: +32 81 60 08 99 | H30: omvang niet geverifieerd
A31: Fiduciaire Dirigeance | B31: Boekhouding | C31: Klein kantoor (2-10 medewerkers) | D31: dirigeance.be | E31: Charleroi | F31: info@dirigeance.be | G31: +32 71 60 98 10 | H31: omvang niet geverifieerd
A32: Fiduciaire Hainaut Tax Consulting | B32: Boekhouding | C32: Klein kantoor (2-10 medewerkers) | D32: ht-consult.be | E32: Tournai | F32: info@ht-consult.be | G32: +32 490 40 52 22 | H32: omvang niet geverifieerd
A33: Fiduciaire Leclef | B33: Boekhouding | C33: Klein kantoor (2-10 medewerkers) | D33: fiduciaire-leclef.be | E33: Charleroi | F33: fiduciaire.leclef@gmail.com | G33: 071 42 34 47 | H33: omvang niet geverifieerd
A34: Fiduciaire Liégeoise | B34: Boekhouding | C34: Klein kantoor (2-10 medewerkers) | E34: Liège | F34: christian.heusicom@fiduciaire-liegeoise.be | G34: +32 4 229 38 68 | H34: persoonlijk adres
A35: Fiduciaire Pardoen | B35: Boekhouding | C35: Klein kantoor (2-10 medewerkers) | D35: pardoen.be | E35: Jumet (Charleroi) | G35: 071 25 93 25 | H35: geen algemeen e-mailadres
A36: Fiduciaire Sobelfisc | B36: Boekhouding | C36: Klein kantoor (2-10 medewerkers) | D36: sobelfisc.com | E36: Namur | F36: fiduciaire@sobelfisc.com | G36: 081 47 07 44 | H36: omvang niet geverifieerd
A37: Fidutop | B37: Boekhouding | C37: Klein kantoor (2-10 medewerkers) | D37: fidutop.be | E37: Liège | F37: info@fidutop.be | G37: 04 247 32 22 | H37: omvang niet geverifieerd
A38: Fiscopti | B38: Boekhouding | C38: Klein kantoor (2-10 medewerkers) | D38: fiscopti.be | E38: Antwerpen | G38: +32 3 257 31 66 | H38: e-mail afgeschermd in zoekresultaat
A39: Fiscorum | B39: Boekhouding | C39: Klein kantoor (2-10 medewerkers) | D39: fiscorum.be | E39: Zwijnaarde (Gent) | F39: info@fiscorum.be | G39: 09 221 57 45 | H39: accountants & belastingconsulenten; omvang niet geverifieerd
A40: Haerts - Dekeyser Accountancy | B40: Boekhouding | C40: Klein kantoor (2-10 medewerkers) | D40: boekhouder.gent | E40: Wondelgem (Gent) | F40: info@hda.gent | G40: +32 9 233 44 98 | H40: omvang niet geverifieerd
...

Sheet Advocaten & consultancy
A1: Bedrijfsnaam | B1: Sector | C1: Subcategorie | D1: Website | E1: Plaats | F1: E-mailadres | G1: Telefoon | H1: Opmerking (omvang / verificatie)
A2: Advocaten Delagrange | B2: Advocaten & consultancy | C2: Klein advocatenkantoor (≤5) | D2: advocatendelagrange.be | E2: Kortrijk | F2: adv@advocatendelagrange.be | G2: 056 22 02 73 | H2: omvang niet geverifieerd
A3: Advocaten Opdebeeck, De Groote & Matthys | B3: Advocaten & consultancy | C3: Klein advocatenkantoor (≤5) | D3: opdebeeckadvocaten.be | E3: Gent | F3: info@opdebeeckadvocaten.be | G3: +32 9 233 67 14 | H3: bouw-, handels- & familierecht
A4: Advocatenassociatie Cooreman-Mertens | B4: Advocaten & consultancy | C4: Klein advocatenkantoor (≤5) | D4: cooremanmertens.be | E4: Zele | F4: info@cooremanmertens.be | G4: 052 44 45 10 | H4: omvang niet geverifieerd
A5: Advocatenkantoor Beele | B5: Advocaten & consultancy | C5: Klein advocatenkantoor (≤5) | D5: be-law.eu | E5: Gent | F5: info@be-law.eu | G5: +32 9 220 99 78 | H5: omvang niet geverifieerd
A6: Advocatenkantoor Brondel, Petitat & Baele | B6: Advocaten & consultancy | C6: Klein advocatenkantoor (≤5) | D6: bpb-advocaten.be | E6: Brugge | F6: contact@bpb-advocaten.be | G6: 050 33 66 03 | H6: omvang niet geverifieerd
A7: Advocatenkantoor Comitius | B7: Advocaten & consultancy | C7: Klein advocatenkantoor (≤5) | D7: comitius.be | E7: Turnhout / Vosselaar / Geel | F7: info@comitius.be | G7: +32 14 70 37 28 | H7: 2 vennoten
A8: Advocatenkantoor D'Hulster | B8: Advocaten & consultancy | C8: Klein advocatenkantoor (≤5) | D8: kantoordhulster.be | E8: Oostende | F8: info@kantoordhulster.be | G8: 059 70 96 32 | H8: 3 advocaten
A9: Advocatenkantoor Dennis Tavernier | B9: Advocaten & consultancy | C9: Klein advocatenkantoor (≤5) | D9: advocaattavernier.be | E9: Oostende | F9: dennis@advocaattavernier.be | G9: +32 59 23 98 15 | H9: persoonlijk adres
A10: Advocatenkantoor Hoet | B10: Advocaten & consultancy | C10: Klein advocatenkantoor (≤5) | D10: hoetadvocatenkantoor.be | E10: Turnhout | F10: hans.hoet@hoetadvocatenkantoor.be | G10: +32 14 41 17 22 | H10: persoonlijk adres
A11: Advocatenkantoor Lefere-Vanderhaeghe | B11: Advocaten & consultancy | C11: Klein advocatenkantoor (≤5) | D11: jvl-advocatenkantoor.be | E11: Roeselare / Sint-Martens-Latem | F11: info@jvl-advocatenkantoor.be | G11: 051 24 36 55 | H11: 2 vennoten
A12: Advocatenkantoor Mallego & Roels | B12: Advocaten & consultancy | C12: Klein advocatenkantoor (≤5) | D12: mallego-roels.be | E12: Aalst | F12: info@mallego-roels.be | G12: +32 475 67 42 79 | H12: 2 vennoten (strafrecht)
A13: Advocatenkantoor Piet Van Eeckhaut | B13: Advocaten & consultancy | C13: Klein advocatenkantoor (≤5) | D13: vaneeckhaut.be | E13: Gent | F13: info@vaneeckhaut.be | G13: 09 225 45 01
A14: Advocatenkantoor Stappers (Turnhout) | B14: Advocaten & consultancy | C14: Klein advocatenkantoor (≤5) | D14: advocaat-turnhout.be | E14: Turnhout | G14: +32 14 70 44 70 | H14: geen e-mail gevonden
A15: Advocatenkantoor Stefaan De Geeter | B15: Advocaten & consultancy | C15: Klein advocatenkantoor (≤5) | D15: degeeter-advocaten.be | E15: Kortrijk | F15: info@degeeter-advocaten.be | G15: 056 22 78 19 | H15: 5 advocaten + 1 medewerker (net boven criterium)
A16: Advocatenkantoor Van den Driessche Karen | B16: Advocaten & consultancy | C16: Klein advocatenkantoor (≤5) | D16: aalst-advocaat.be | E16: Aalst | G16: 053 70 66 41 | H16: geen e-mail gevonden
A17: Advocatenkantoor Van der Elst | B17: Advocaten & consultancy | C17: Klein advocatenkantoor (≤5) | D17: vdelst.be | E17: Aalst | F17: advocaat@vdelst.be | G17: +32 53 70 44 64
A18: Advocatenkantoor Vantyghem-Vandeputte | B18: Advocaten & consultancy | C18: Klein advocatenkantoor (≤5) | D18: vantyghem-vandeputte.be | E18: Roeselare | G18: +32 51 26 83 00 | H18: 4 advocaten; geen e-mail gevonden
A19: Advokomvest | B19: Advocaten & consultancy | C19: Klein advocatenkantoor (≤5) | D19: advokomvest.be | E19: Brugge | F19: info@advokomvest.be | G19: 050 44 00 60 | H19: omvang niet geverifieerd
A20: Advonet Leuven (Advocatenkantoor Feremans) | B20: Advocaten & consultancy | C20: Klein advocatenkantoor (≤5) | D20: advonet-leuven.be | E20: Wilsele (Leuven) | F20: leuven@advonet.be | G20: 0476 64 14 80 | H20: omvang niet geverifieerd
A21: Aves Legal | B21: Advocaten & consultancy | C21: Klein advocatenkantoor (≤5) | D21: aveslegal.be | E21: Heverlee (Leuven) | G21: 016 31 04 20 | H21: geen e-mail gevonden
A22: Beelen Advocaten | B22: Advocaten & consultancy | C22: Klein advocatenkantoor (≤5) | D22: beelen-advocaten.be | E22: Leuven | F22: bertbeelen@beelenadvocaten.be | G22: 016 31 77 10 | H22: persoonlijk adres
A23: Bollen Advocaten | B23: Advocaten & consultancy | C23: Klein advocatenkantoor (≤5) | D23: bollenadvocaten.be | E23: Leuven | G23: +32 16 23 11 13 | H23: arbeidsrecht; geen e-mail gevonden
A24: Callebaut & Van Thienen Advocaten (CVT) | B24: Advocaten & consultancy | C24: Klein advocatenkantoor (≤5) | D24: cvt-advocaten.be | E24: Erembodegem (Aalst) | F24: info@cvt-advocaten.be | G24: 053 22 90 86 | H24: omvang niet geverifieerd
A25: CEPA Advocaten | B25: Advocaten & consultancy | C25: Klein advocatenkantoor (≤5) | D25: cepa-advocaten.be | E25: Aalst | F25: info@cepa-advocaten.be | G25: +32 53 40 02 90 | H25: omvang niet geverifieerd
A26: Clavis Advocaten | B26: Advocaten & consultancy | C26: Klein advocatenkantoor (≤5) | D26: clavisadvocaten.be | E26: Leuven | F26: kristel.jansens@clavisadvocaten.be | G26: +32 16 22 24 45 | H26: kleinschalig kantoor; persoonlijk adres
A27: De Broeck Van Laere & Partners | B27: Advocaten & consultancy | C27: Klein advocatenkantoor (≤5) | D27: dvp-law.com | E27: Koekelberg | F27: secretariaat@dvp-law.com | G27: +32 2 423 00 42 | H27: omvang niet geverifieerd
A28: De Gendt Advocaten | B28: Advocaten & consultancy | C28: Klein advocatenkantoor (≤5) | D28: degendtadvocaten.be | E28: Gent | F28: info@degendtadvocaten.be | H28: omvang niet geverifieerd
A29: De Ridder, Lahousse & Partners | B29: Advocaten & consultancy | C29: Klein advocatenkantoor (≤5) | D29: deridder-law.be | E29: Mechelen | F29: advocaat@deridder-law.be | H29: geen telefoon in zoekresultaat
A30: Delbrouck & Daeninck Advocaten | B30: Advocaten & consultancy | C30: Klein advocatenkantoor (≤5) | D30: delbrouck-daeninck.be | E30: Hasselt | F30: info@delbrouck-daeninck.be | G30: 011 21 53 15 | H30: een van de grotere kantoren in Hasselt; mogelijk >5 medewerkers
A31: Devos & Van Den Eynde Advocatenassociatie | B31: Advocaten & consultancy | C31: Klein advocatenkantoor (≤5) | D31: devosvde-law.be | E31: Geel | G31: +32 14 58 55 18 | H31: full-service; geen e-mail gevonden
A32: ETHOS Advocaten | B32: Advocaten & consultancy | C32: Klein advocatenkantoor (≤5) | D32: ethosadvocaten.be | E32: Leuven | F32: info@ethosadvocaten.be | G32: 016 22 24 57
A33: Exacto Advocaten | B33: Advocaten & consultancy | C33: Klein advocatenkantoor (≤5) | D33: exacto-advocaten.be | E33: Hasselt | F33: info@exacto-advocaten.be | G33: 011 23 30 64 | H33: advocaten voor ondernemingen; omvang niet geverifieerd
A34: Forum Advocaten | B34: Advocaten & consultancy | C34: Klein advocatenkantoor (≤5) | D34: forumadvocaten.be | E34: Antwerpen | F34: info@forumadvocaten.be | G34: +32 3 369 95 65 | H34: omvang niet geverifieerd
A35: GD&A Advocaten | B35: Advocaten & consultancy | C35: Klein advocatenkantoor (≤5) | D35: gdena-advocaten.be | E35: Mechelen | F35: info@gdena-advocaten.be | G35: 015 40 49 40 | H35: omvang niet geverifieerd
A36: Heger Association | B36: Advocaten & consultancy | C36: Klein advocatenkantoor (≤5) | D36: avocatsheger.be | E36: Namur | F36: info@avocatsheger.be | G36: +32 81 23 08 13
A37: Hoefkens Advocaten | B37: Advocaten & consultancy | C37: Klein advocatenkantoor (≤5) | D37: hvdw.be | E37: Lille / Geel | F37: info@hvdw.be | G37: 0477 32 25 85
A38: HTPC Avocats | B38: Advocaten & consultancy | C38: Klein advocatenkantoor (≤5) | D38: htpc-avocats.be | E38: Jambes (Namur) | F38: info@htpc-avocats.be | G38: 081 74 42 04 | H38: 4 vennoten
A39: Koraal Advocaten & Bemiddelaars | B39: Advocaten & consultancy | C39: Klein advocatenkantoor (≤5) | D39: koraaladvocaten.com | E39: Hasselt (+ Bilzen, Tessenderlo, Maasmechelen) | F39: info@koraaladvocaten.com | G39: +32 11 25 20 20 | H39: meerdere zitdagplaatsen; mogelijk >5 medewerkers
A40: Leges | B40: Advocaten & consultancy | C40: Klein advocatenkantoor (≤5) | D40: leges.be | E40: Liège | F40: info@leges.be | G40: +32 4 344 06 60 | H40: omvang niet geverifieerd
...

Sheet Transport & logistiek
A1: Bedrijfsnaam | B1: Sector | C1: Subcategorie | D1: Website | E1: Plaats | F1: E-mailadres | G1: Telefoon | H1: Opmerking (omvang / verificatie)
A2: B.B. Trans | B2: Transport & logistiek | C2: Transportbedrijf (eigen wagenpark) | D2: bbtrans.be | E2: Holsbeek | G2: 016 56 38 59 | H2: koel- & expresstransport; geen e-mail gevonden
A3: Benelux Trans | B3: Transport & logistiek | C3: Transportbedrijf (eigen wagenpark) | D3: beneluxtrans.be | E3: Groot-Bijgaarden (Dilbeek) | G3: +32 2 463 51 51 | H3: familiebedrijf sinds 1928, koeltransport; mogelijk >40 werknemers; contact via formulier
A4: Bevertrans | B4: Transport & logistiek | C4: Transportbedrijf (eigen wagenpark) | D4: bevertrans.be | E4: Veldegem (Zedelgem) | F4: info@bevertrans.be | G4: +32 50 28 99 69 | H4: tankcontainer- en kippertransport; omvang niet geverifieerd
A5: Danny Trans | B5: Transport & logistiek | C5: Transportbedrijf (eigen wagenpark) | D5: dannytrans.be | E5: Bilzen | F5: danny.trans@skynet.be | G5: +32 11 33 30 35 | H5: distributie, express & kraantransport
A6: De Nobele Transport | B6: Transport & logistiek | C6: Transportbedrijf (eigen wagenpark) | D6: denobeletransport.be | E6: Lubbeek | F6: de_nobele_transport@hotmail.be | G6: 0471 24 64 54
A7: Demunster Depannage & Transport | B7: Transport & logistiek | C7: Transportbedrijf (eigen wagenpark) | D7: depannagedemunster.be | E7: Zwevegem | F7: move@demunster.be | G7: +32 56 25 89 25 | H7: takeldienst & machinetransport sinds 1989
A8: Desimpel Trans | B8: Transport & logistiek | C8: Transportbedrijf (eigen wagenpark) | D8: desimpel-trans.be | E8: Ichtegem | G8: +32 51 58 06 44 | H8: kipper- en tractievervoer; contact via formulier
A9: Distributie Govaerts | B9: Transport & logistiek | C9: Transportbedrijf (eigen wagenpark) | D9: distributiegovaerts.be | E9: Kortessem | F9: info@distributiegovaerts.be | G9: +32 477 30 13 45 | H9: sinds 1997; 24/7
A10: E.T.L. European Transport & Logistics | B10: Transport & logistiek | C10: Transportbedrijf (eigen wagenpark) | D10: etltransport.be | E10: Genk | F10: info@etltransport.be | G10: +32 89 84 11 22 | H10: sinds 1992
A11: GOBO Transport & Logistics | B11: Transport & logistiek | C11: Transportbedrijf (eigen wagenpark) | D11: gobo.eu | E11: Lanaken | F11: info@gobo.eu | G11: +32 89 71 00 70 | H11: familiebedrijf sinds 1963; mogelijk >40 werknemers
A12: Heeze Transport Logistiek Belgium | B12: Transport & logistiek | C12: Transportbedrijf (eigen wagenpark) | E12: Lochristi | G12: +32 9 355 60 98 | H12: geen e-mail gevonden
A13: Internationaal Transport Gilbert De Clercq | B13: Transport & logistiek | C13: Transportbedrijf (eigen wagenpark) | D13: gilbertdeclercq.com | E13: Temse / Sint-Niklaas | F13: info@gilbertdeclercq.com | G13: +32 3 775 74 26 | H13: familiebedrijf sinds 1957; mogelijk >40 werknemers
A14: K & E Trucking (Cool Traffic) | B14: Transport & logistiek | C14: Transportbedrijf (eigen wagenpark) | D14: cooltraffic.be | E14: Oudenaarde | F14: info@ke-trucking.com | G14: +32 55 45 79 01 | H14: ±60 koeltransporteenheden; mogelijk >40 werknemers
A15: KMS & CO | B15: Transport & logistiek | C15: Transportbedrijf (eigen wagenpark) | D15: kms-co.be | E15: Meise | F15: info@kms-co.be | G15: 0484 02 89 98 | H15: pakket- & goederentransport
A16: KTS Transport | B16: Transport & logistiek | C16: Transportbedrijf (eigen wagenpark) | D16: kts-bvba.com | E16: Wilrijk (Antwerpen) | F16: info@kts-bvba.com | G16: +32 3 770 79 09 | H16: container- & goederentransport
A17: LD Trans | B17: Transport & logistiek | C17: Transportbedrijf (eigen wagenpark) | D17: ld-trans.be | E17: Kortessem | F17: ld-trans@outlook.be | G17: +32 12 74 40 57 | H17: transport & opslag, sinds 2005
A18: Mervielde | B18: Transport & logistiek | C18: Transportbedrijf (eigen wagenpark) | D18: mervielde.be | E18: Ertvelde (Evergem) | F18: transport@mervielde.be | G18: +32 9 341 96 96 | H18: tanktransport; mogelijk >40 werknemers
A19: Nieuwenhuyse | B19: Transport & logistiek | C19: Transportbedrijf (eigen wagenpark) | D19: nieuwenhuyse.be | E19: Moen (Zwevegem) | F19: info@nieuwenhuyse.be | G19: 056 75 51 00 | H19: Goederenvervoer Benelux sinds 1953
A20: NV Transport De Vreese | B20: Transport & logistiek | C20: Transportbedrijf (eigen wagenpark) | D20: devreesetransport.be | E20: Oostakker (Gent) | F20: geert@devreesetransport.be | G20: 09 252 27 37 | H20: persoonlijk adres zaakvoerder; kraan-/diepladertransport
A21: Peethultra Transport | B21: Transport & logistiek | C21: Transportbedrijf (eigen wagenpark) | D21: peethultra.be | E21: Westmalle (Malle) | F21: info@peethultra.be | G21: 03 312 05 31 | H21: gerechtelijke reorganisatie afgesloten sept. 2025 — status nakijken
A22: S'Jegers Transport | B22: Transport & logistiek | C22: Transportbedrijf (eigen wagenpark) | D22: sjegers.eu | E22: Laakdal | F22: info@sjegers.eu | G22: +32 13 67 78 23 | H22: mogelijk >40 werknemers
A23: Toco-Trans | B23: Transport & logistiek | C23: Transportbedrijf (eigen wagenpark) | D23: toco-trans.be | E23: Grembergen (Dendermonde) | G23: +32 478 74 40 71 | H23: gsm zaakvoerder; geen e-mail gevonden
A24: Trans Alleman | B24: Transport & logistiek | C24: Transportbedrijf (eigen wagenpark) | D24: transalleman.be | E24: Geluwe (Wervik) | H24: milieutransport (o.a. voor Vanheede); contact via website
A25: Transport De Laet | B25: Transport & logistiek | C25: Transportbedrijf (eigen wagenpark) | D25: transportdelaet.wordpress.com | E25: Elewijt (Zemst) | G25: 015 61 13 51 | H25: tanktransport; geen e-mail gevonden
A26: Transport De Sauter | B26: Transport & logistiek | C26: Transportbedrijf (eigen wagenpark) | D26: desauter.be | E26: Brugge | G26: +32 50 31 81 41 | H26: familiebedrijf; geen e-mail gevonden
A27: Transport Demyttenaere & Co | B27: Transport & logistiek | C27: Transportbedrijf (eigen wagenpark) | D27: transportdemyttenaere.be | E27: Rumbeke (Roeselare) | F27: info@transportdemyttenaere.be | G27: +32 51 25 16 03 | H27: sinds 1971
A28: Transport Fransen J. | B28: Transport & logistiek | C28: Transportbedrijf (eigen wagenpark) | E28: Putte | G28: +32 15 73 09 04 | H28: familiebedrijf, 60+ jaar; sinds 2024 overgenomen door Corneel Geerts; geen publiek e-mailadres gevonden
A29: Transport Kris De Leeneer | B29: Transport & logistiek | C29: Transportbedrijf (eigen wagenpark) | E29: Lokeren | G29: +32 52 35 43 10 | H29: geen e-mail gevonden
A30: Transport Macharis | B30: Transport & logistiek | C30: Transportbedrijf (eigen wagenpark) | D30: transport-macharis.be | E30: Dendermonde | F30: info@transport-macharis.be | G30: +32 52 21 17 49 | H30: familiebedrijf
A31: Transport Miquel Declercq | B31: Transport & logistiek | C31: Transportbedrijf (eigen wagenpark) | D31: transport-miquel-declercq.be | E31: Harelbeke | G31: 0494 15 56 45 | H31: geen e-mail gevonden; omvang niet geverifieerd
A32: Transport Roosens | B32: Transport & logistiek | C32: Transportbedrijf (eigen wagenpark) | D32: roosens.be | E32: Haasdonk (Beveren) | F32: roosens@roosens.be | G32: +32 3 775 01 01 | H32: container-/tanktransport; mogelijk >40 werknemers
A33: Transport Stekelorum | B33: Transport & logistiek | C33: Transportbedrijf (eigen wagenpark) | D33: transportstekelorum.be | E33: Vleteren (Oostvleteren) | F33: info@stekelorumtransport.be | G33: 057 40 01 82 | H33: ±25 vrachtwagens; familiebedrijf
A34: Transport Van de Velde | B34: Transport & logistiek | C34: Transportbedrijf (eigen wagenpark) | D34: transportvandevelde.be | E34: Wetteren | F34: info@transportvandevelde.be | G34: +32 9 252 12 25
A35: Transport Van Heesvelde | B35: Transport & logistiek | C35: Transportbedrijf (eigen wagenpark) | D35: mervielde.be | E35: Ertvelde (Evergem) | F35: transport@van-heesvelde.be | G35: +32 9 341 96 80 | H35: zusterbedrijf van Mervielde
A36: Transport Van Renterghem | B36: Transport & logistiek | C36: Transportbedrijf (eigen wagenpark) | D36: trans-tvr.be | E36: Deinze | F36: info@trans-tvr.be | G36: 09 387 00 57 | H36: familiebedrijf, volle ladingen
A37: Transport Verbeken | B37: Transport & logistiek | C37: Transportbedrijf (eigen wagenpark) | D37: verbekentrans.be | E37: Dendermonde | F37: info@verbekentrans.be | G37: +32 52 21 68 16 | H37: Vloeibare voeding, sinds 1965
A38: Transport W. Franssens | B38: Transport & logistiek | C38: Transportbedrijf (eigen wagenpark) | E38: Verrebroek (Beveren) | G38: +32 3 789 30 41 | H38: geen e-mail gevonden
A39: Travadri | B39: Transport & logistiek | C39: Transportbedrijf (eigen wagenpark) | D39: travadri.com | E39: Merelbeke | G39: 09 230 42 33 | H39: groupage België–Frankrijk; geen e-mail gevonden
A40: Trippaers Transport | B40: Transport & logistiek | C40: Transportbedrijf (eigen wagenpark) | D40: trippaers.com | E40: Genk | G40: +32 89 35 66 00 | H40: geen e-mail gevonden
...

Sheet Bouw
A1: Bedrijfsnaam | B1: Sector | C1: Subcategorie | D1: Website | E1: Plaats | F1: E-mailadres | G1: Telefoon | H1: Opmerking (omvang / verificatie)
A2: AK Building Woningbouw & Renovatie | B2: Bouw | C2: Algemene aannemer | D2: akbuilding.be | E2: Zonhoven | F2: info@akbuilding.be | G2: +32 483 51 24 67 | H2: ruwbouw & totaalrenovatie
A3: ALFA•VAF | B3: Bouw | C3: Algemene aannemer | D3: alfavaf.be | E3: Eksaarde (Lokeren) | F3: info@alfavaf.be | G3: +32 468 29 00 85 | H3: omvang niet geverifieerd
A4: Algemene Bouwonderneming Debal Erik | B4: Bouw | C4: Algemene aannemer | D4: bouwondernemingdebalerik.be | E4: Roeselare | F4: info@debalerik.be | G4: 051 20 83 41 | H4: >50 jaar actief
A5: Algemene Bouwonderneming Toon Willems | B5: Bouw | C5: Algemene aannemer | D5: abtoonwillems.be | E5: Geel | F5: info@abtoonwillems.be | G5: 0498 57 54 45 | H5: omvang niet geverifieerd
A6: Algemene Bouwwerken Steven Kegels | B6: Bouw | C6: Algemene aannemer | D6: abstevenkegelsbv.be | E6: Sint-Niklaas | G6: 0478 36 00 39 | H6: e-mail afgeschermd op website
A7: All-Bouw | B7: Bouw | C7: Algemene aannemer | D7: allbouw.com | E7: Roeselare | F7: info@allbouw.com | G7: +32 51 25 30 25 | H7: nieuwbouw, renovatie & restauratie
A8: AMD Bouw | B8: Bouw | C8: Algemene aannemer | D8: amdbouw.be | E8: Sint-Laureins | G8: 0467 74 81 62 | H8: e-mail afgeschermd; bouw, elektriciteit, sanitair
A9: Arco Villa | B9: Bouw | C9: Algemene aannemer | D9: arcovilla.be | E9: Sprimont | F9: fm@arcovilla.be | G9: +32 4 372 15 92 | H9: >25 jaar; adres lijkt persoonsgebonden
A10: ARP Bouw & Interieur | B10: Bouw | C10: Algemene aannemer | D10: arp-bouw.be | E10: Hasselt | F10: info@arp-bouw.be | G10: +32 472 43 82 79 | H10: sinds 2010
A11: Audenaert Eddy & Zonen | B11: Bouw | C11: Algemene aannemer | D11: audenaertconstruct.be | E11: Sint-Niklaas | G11: +32 3 776 57 01 | H11: geen publiek e-mailadres gevonden
A12: Bouwbedrijf Gevaco | B12: Bouw | C12: Algemene aannemer | D12: bouwbedrijfgevaco.be | E12: Mol | F12: info@bouwbedrijfgevaco.be | G12: 014 71 64 54
A13: Bouwonderneming De Clippel | B13: Bouw | C13: Algemene aannemer | D13: declippel.be | E13: Herzele | F13: info@declippel.be | G13: 053 62 24 55 | H13: erkend aannemer klasse 5 sinds 1945; mogelijk >30 werknemers
A14: Bouwonderneming Kris Van Ostaeyen | B14: Bouw | C14: Algemene aannemer | D14: krisvanostaeyen.be | E14: Zandhoven | F14: info@krisvanostaeyen.be | G14: 0477 45 76 88 | H14: ruwbouw & renovatie
A15: Bouwwerken Goderis | B15: Bouw | C15: Algemene aannemer | D15: bouwwerkengoderis.be | E15: Tielt | G15: 0479 13 01 10 | H15: geen e-mail gevonden
A16: C/B Bouw | B16: Bouw | C16: Algemene aannemer | E16: West-Vlaanderen | G16: 050 54 66 52 | H16: geen e-mail gevonden
A17: DC Technic | B17: Bouw | C17: Algemene aannemer | D17: dcbouw.com | E17: Leuven | F17: info@dcbouw.com | H17: aannemer & schrijnwerkerij; geen telefoon in zoekresultaat
A18: Deruyck Bouwonderneming | B18: Bouw | C18: Algemene aannemer | D18: deruyckbouw.be | E18: Roeselare | F18: info@deruyckbouw.be | G18: 051 20 26 03 | H18: familiebedrijf; omvang niet geverifieerd
A19: Heres Bouwprojecten | B19: Bouw | C19: Algemene aannemer | D19: heres-bouw.be | E19: Oud-Turnhout | F19: info@heres-bouw.be | G19: +32 473 96 11 09 | H19: omvang niet geverifieerd
A20: Houtbouw Kempen | B20: Bouw | C20: Algemene aannemer | D20: houtbouwkempen.be | E20: Mol | F20: info@houtbouwkempen.be | G20: +32 473 64 64 19 | H20: houtskeletbouw; omvang niet geverifieerd
A21: Industriebouw Vaneenoo | B21: Bouw | C21: Algemene aannemer | D21: vaneenoo.be | E21: Wingene | G21: +32 51 65 61 78 | H21: geen algemeen e-mailadres gevonden
A22: K&W Construction | B22: Bouw | C22: Algemene aannemer | D22: kwconstruction.be | E22: Wortegem-Petegem | F22: info@kwconstruction.be | G22: +32 55 45 79 73 | H22: omvang niet geverifieerd
A23: KBX Bouwonderneming | B23: Bouw | C23: Algemene aannemer | D23: kbxbvba.be | E23: Herentals | F23: info@kbxbvba.be | G23: +32 471 60 16 22 | H23: omvang niet geverifieerd
A24: LeF! | B24: Bouw | C24: Algemene aannemer | D24: bouwenmetlef.be | E24: Mol | F24: info@bouwenmetlef.be | G24: 0468 48 64 82 | H24: nieuwbouw en renovatie; omvang niet geverifieerd
A25: Ooms Woonrealisaties | B25: Bouw | C25: Algemene aannemer | D25: ooms.be | E25: Rijkevorsel | F25: info@ooms.be | G25: +32 3 309 09 09 | H25: totaalaannemer; mogelijk >30 werknemers
A26: Standing Construct | B26: Bouw | C26: Algemene aannemer | D26: standingconstruct.be | E26: Geel | F26: info@standingconstruct.be | G26: +32 14 58 27 20 | H26: 4e generatie, eigen vaklui; omvang niet geverifieerd
A27: Stonehouse | B27: Bouw | C27: Algemene aannemer | D27: stonehouse.be | E27: Boutersem | F27: info@stonehouse.be | G27: +32 475 47 46 96
A28: Van der Steen Algemene Bouwonderneming | B28: Bouw | C28: Algemene aannemer | D28: van-der-steen.be | E28: Leuven | F28: info@van-der-steen.be | G28: 016 48 94 17
A29: Woestenborghs Bouwbedrijf | B29: Bouw | C29: Algemene aannemer | D29: woestenborghs-bouwbedrijf.be | E29: Merksplas | G29: +32 14 63 38 04 | H29: geen algemeen e-mailadres gevonden
A30: Woningbouw Vens | B30: Bouw | C30: Algemene aannemer | D30: vens.be | E30: Zwevezele (Wingene) | F30: info@vens.be | G30: 051 61 12 19 | H30: sleutel-op-de-deur
A31: XL Construction | B31: Bouw | C31: Algemene aannemer | D31: xlconstruction.be | E31: Pousset (Remicourt) | F31: info@xlconstruction.be | G31: 04 332 26 10 | H31: sleutel-op-de-deur, Wallonië
A32: Algemene Elektriciteitswerken Jordy Danckaert | B32: Bouw | C32: Installatiebedrijf (elektriciteit) | D32: jordydanckaert.be | E32: Grembergen (Dendermonde) | F32: info@jordydanckaert.be | G32: 0476 07 52 98 | H32: omvang niet geverifieerd
A33: Brackx Elektriciteitswerken | B33: Bouw | C33: Installatiebedrijf (elektriciteit) | D33: e-brackx.be | E33: Oostende | F33: info@e-brackx.be | G33: 0497 29 15 80 | H33: omvang niet geverifieerd
A34: CL Electric | B34: Bouw | C34: Installatiebedrijf (elektriciteit) | D34: clelectric.be | E34: Oostende | G34: +32 477 89 41 40 | H34: geen publiek e-mailadres gevonden
A35: De Hondt Elektriciteitswerken | B35: Bouw | C35: Installatiebedrijf (elektriciteit) | D35: dehondtelektriciteitswerken.be | E35: Diepenbeek | F35: info@dehondtelektriciteitswerken.be | G35: 0468 15 01 22 | H35: omvang niet geverifieerd
A36: Denis Wilrijkse Electrowerken | B36: Bouw | C36: Installatiebedrijf (elektriciteit) | D36: deniswilrijkelectro.be | E36: Wilrijk (Antwerpen) | F36: info@deniswilrijkelectro.be | G36: 0476 02 97 02 | H36: sinds 1960; omvang niet geverifieerd
A37: Electro Corbeels | B37: Bouw | C37: Installatiebedrijf (elektriciteit) | D37: corbeels.be | E37: Holsbeek | F37: info@corbeels.be | G37: +32 16 23 87 11 | H37: residentieel & industrieel
A38: Elektriciteitswerken Vanhaverbeke | B38: Bouw | C38: Installatiebedrijf (elektriciteit) | D38: elektriciteitswerkenvanhaverbeke.be | E38: Izegem | F38: info@elektriciteitswerkenvanhaverbeke.be | G38: +32 472 27 00 90 | H38: omvang niet geverifieerd
A39: Elektro Jos | B39: Bouw | C39: Installatiebedrijf (elektriciteit) | D39: elektrojos.be | E39: Izegem | F39: info@elektrojos.be | G39: +32 476 85 56 66 | H39: omvang niet geverifieerd
A40: ENW Elektriciteitswerken | B40: Bouw | C40: Installatiebedrijf (elektriciteit) | D40: enwelektriciteitswerken.be | E40: Aarschot (Rillaar) | G40: +32 16 50 31 24 | H40: geen e-mail gevonden
...

Sheet Vastgoed
A1: Bedrijfsnaam | B1: Sector | C1: Subcategorie | D1: Website | E1: Plaats | F1: E-mailadres | G1: Telefoon | H1: Opmerking (omvang / verificatie)
A2: Abricasa | B2: Vastgoed | C2: Makelaarskantoor | D2: abricasa.be | E2: Antwerpen | F2: info@abricasa.be | G2: 03 259 04 04 | H2: BIV 506656
A3: AC Vastgoed | B3: Vastgoed | C3: Makelaarskantoor | D3: acvastgoed.be | E3: Sint-Niklaas | F3: info@acvastgoed.be | G3: 03 777 93 93
A4: AD-IMMO | B4: Vastgoed | C4: Makelaarskantoor | D4: ad-immo.be | E4: Namur | F4: info@ad-immo.be | G4: 081 74 73 75
A5: AG Immobilière | B5: Vastgoed | C5: Makelaarskantoor | D5: agimmobiliere.be | E5: Rocourt (Liège) | F5: info@agimmobiliere.be | G5: 04 233 55 55
A6: Agence Rosseel | B6: Vastgoed | C6: Makelaarskantoor | D6: rosseel.be | E6: Gent | G6: 09 220 50 00 | H6: alleen persoonlijke e-mailadressen; verkoop, verhuur, rentmeesterschap
A7: Axel Lenaerts Makelaars | B7: Vastgoed | C7: Makelaarskantoor | D7: axellenaerts.be | E7: Gent / Oudenaarde | F7: info@axellenaerts.be | G7: 09 245 24 24 | H7: meerdere kantoren
A8: BM Vastgoed | B8: Vastgoed | C8: Makelaarskantoor | D8: bmvastgoed.be | E8: Mechelen / Leuven | F8: info@bmvastgoed.be | G8: 015 79 15 99 | H8: 2 kantoren
A9: Bricx Vastgoed (Kortrijk) | B9: Vastgoed | C9: Makelaarskantoor | D9: bricx.be | E9: Kortrijk | F9: kortrijk@bricx.be | G9: 056 36 03 00 | H9: meerdere kantoren
A10: Claves Vastgoed | B10: Vastgoed | C10: Makelaarskantoor | D10: claves.be | E10: Sint-Niklaas | F10: vastgoed@claves.be | G10: +32 3 502 98 74
A11: Copandi | B11: Vastgoed | C11: Makelaarskantoor | D11: copandi.be | E11: Mechelen / Lier | F11: info@copandi.be | G11: +32 15 79 46 44 | H11: meerdere kantoren
A12: Cornelis Goeman | B12: Vastgoed | C12: Makelaarskantoor | D12: cornelis-goeman.be | E12: Merelbeke / Lede (+ 6 kantoren) | F12: immo@cornelis-partners.be | G12: +32 9 232 21 50 | H12: 8 kantoren in Oost-Vlaanderen
A13: De Boer & Partners (Turnhout) | B13: Vastgoed | C13: Makelaarskantoor | D13: deboerenpartners.be | E13: Turnhout | F13: karen.woestenborghs@deboerenpartners.be | G13: +32 14 22 42 00 | H13: persoonlijk adres; meerdere kantoren
A14: De Makelaardij | B14: Vastgoed | C14: Makelaarskantoor | D14: demakelaardij.be | E14: Mechelen | F14: info@demakelaardij.be | G14: 015 20 20 82
A15: De Vastgoedkoning | B15: Vastgoed | C15: Makelaarskantoor | D15: devastgoedkoning.be | E15: Aarschot | F15: info@devastgoedkoning.be | G15: 016 78 95 55
A16: Dicasa | B16: Vastgoed | C16: Makelaarskantoor | D16: dicasa.be | E16: Roeselare (Beveren) | F16: info@dicasa.be | G16: 051 20 14 00 | H16: ook syndicus
A17: Diksimmo | B17: Vastgoed | C17: Makelaarskantoor | D17: diksimmo.be | E17: Ieper / Diksmuide | F17: ieper@diksimmo.be | G17: +32 57 79 75 00
A18: Dor & Bleus | B18: Vastgoed | C18: Makelaarskantoor | D18: immodorbleus.be | E18: Liège | F18: dor@dorbleus.be | G18: +32 4 223 21 88 | H18: sinds 2012
A19: Elissa Agence Immobilière | B19: Vastgoed | C19: Makelaarskantoor | D19: immoelissa.be | E19: Liège | F19: info@immoelissa.be | G19: 04 221 02 21
A20: ERA Domus | B20: Vastgoed | C20: Makelaarskantoor | D20: era.be | E20: Ieper (+ Veurne, Diksmuide, Poperinge, Roeselare) | F20: domus.ieper@era.be | G20: +32 57 21 36 96 | H20: meerdere kantoren
A21: ERA Wonen Sint-Niklaas | B21: Vastgoed | C21: Makelaarskantoor | D21: era.be | E21: Sint-Niklaas | F21: hello@era.be | G21: +32 3 269 37 69 | H21: ERA-netwerk; algemeen adres van ERA
A22: Heylen Vastgoed Mechelen | B22: Vastgoed | C22: Makelaarskantoor | D22: heylenvastgoed.be | E22: Mechelen | F22: info@heylenexclusief.be | G22: 0800 292 23 | H22: groot netwerk; adres van Heylen Exclusief
A23: Huiskantoor | B23: Vastgoed | C23: Makelaarskantoor | D23: huiskantoor.be | E23: Lommel / Pelt / Bree | F23: info@huiskantoor.be | G23: 011 91 90 50 | H23: 3 kantoren
A24: Huys Noord Immobiliën | B24: Vastgoed | C24: Makelaarskantoor | D24: huysnoord.be | E24: Brugge | F24: contact@huysnoord.be | G24: 050 70 06 00
A25: Huyzen Sint-Niklaas | B25: Vastgoed | C25: Makelaarskantoor | D25: huyzen.be | E25: Belsele (Sint-Niklaas) | G25: 03 775 03 30 | H25: deel van Huyzen Vastgoedgroep; e-mail afgeschermd
A26: i-Moov | B26: Vastgoed | C26: Makelaarskantoor | D26: i-moov.be | E26: Gent | F26: info@i-moov.be | G26: +32 9 225 50 50 | H26: aantal panden niet geverifieerd
A27: Immo Consulting Wallays | B27: Vastgoed | C27: Makelaarskantoor | D27: immowallays.be | E27: Roeselare | G27: 051 24 88 00 | H27: familiekantoor >50 jaar; geen e-mail gevonden
A28: Immo Da Vinci | B28: Vastgoed | C28: Makelaarskantoor | D28: immodavinci.be | E28: Gent | F28: info@immodavinci.be | G28: 09 273 55 55
A29: Immo Francois | B29: Vastgoed | C29: Makelaarskantoor | D29: immofrancois.be | E29: Loppem (Zedelgem) – 24 kantoren | F29: dries@immofrancois.be | G29: 050 32 34 34 | H29: netwerk van 24 kantoren; persoonlijk adres
A30: Immo GVE | B30: Vastgoed | C30: Makelaarskantoor | D30: immogve.be | E30: Leuven (+ Tienen, Aarschot, Bertem) | F30: info@immogve.be | G30: 016 56 56 14 | H30: 4 kantoren
A31: Immo Jo | B31: Vastgoed | C31: Makelaarskantoor | D31: jo.immo | E31: Oostende | F31: jo@jo.immo | G31: +32 59 30 08 00
A32: Immo Minnaert & C° | B32: Vastgoed | C32: Makelaarskantoor | D32: immominnaert.be | E32: Hasselt | F32: patrick@immominnaert.be | G32: +32 11 21 44 53 | H32: persoonlijk adres
A33: Immo Sleutel | B33: Vastgoed | C33: Makelaarskantoor | D33: immosleutel.be | E33: Brugge | F33: info@immosleutel.be | G33: +32 50 70 70 70
A34: Immo Vastgoed Turnhout | B34: Vastgoed | C34: Makelaarskantoor | D34: vastgoedturnhout.be | E34: Turnhout | F34: info@vastgoedturnhout.be | G34: 014 42 33 85 | H34: sinds 1992
A35: imo Vastgoed Mechelen | B35: Vastgoed | C35: Makelaarskantoor | D35: imovastgoed.be | E35: Mechelen | G35: +32 479 88 27 55 | H35: deel van imo Vastgoed Groep; e-mail niet in zoekresultaat
A36: INFORIM | B36: Vastgoed | C36: Makelaarskantoor | D36: inforim.be | E36: Liège | F36: info@inforim.be | H36: geen telefoon in zoekresultaat
A37: L'Immobilière L.A. | B37: Vastgoed | C37: Makelaarskantoor | D37: agence-immobiliere-namur.be | E37: Namur | F37: contact@agence-immobiliere-namur.be | H37: geen telefoon in zoekresultaat
A38: La Signature | B38: Vastgoed | C38: Makelaarskantoor | D38: lasignature.be | E38: Hognoul / Embourg (Liège) | F38: info@lasignature.be | G38: 04 223 30 30 | H38: 2 kantoren
A39: Loontjens & Lagast Vastgoed | B39: Vastgoed | C39: Makelaarskantoor | D39: llvastgoed.be | E39: Brugge | F39: info@llvastgoed.be | G39: +32 50 20 02 00
A40: Makelaarshuys | B40: Vastgoed | C40: Makelaarskantoor | D40: makelaarshuys.be | E40: Gent | F40: alain@makelaarshuys.be | G40: 09 277 10 27 | H40: persoonlijk adres; aantal panden niet geverifieerd
...
